Workbook
Name Data_Consolidado: Table2[#All]
Name Slicer_Apt: #N/A

Sheet INCOME
A1: Check-in Date | B1: Check-out Date | C1: Num_Nights | D1: APARTMENT | E1: NAME | F1: FULL AMOUNT usd | G1: FULL AMOUNT mxn pesos | H1: 20% commission | I1: RENTAL PLATFORM | J1: Month
A2: 44635 | B2: 44638 | C2: =Table1[[#This Row],[Check-out Date]]-Table1[[#This Row],[Check-in Date]] -> 3 | D2: B303 | E2: Emmeline Page | F2: 336.29 | G2: =Table1[[#This Row],[FULL AMOUNT usd]]*20 -> 6725.8 | H2: =F2*0.2 -> 67.258 | I2: Airbnb | J2: =YEAR(A2)&"-"&TEXT(MONTH(A2),"00") -> 2022-03
A3: 44635 | B3: 44640 | C3: =Table1[[#This Row],[Check-out Date]]-Table1[[#This Row],[Check-in Date]] -> 5 | D3: A302 | E3: Spencer Lanier | F3: 533.36 | G3: =Table1[[#This Row],[FULL AMOUNT usd]]*20 -> 10667.2 | H3: =F3*0.2 -> 106.672 | I3: Airbnb | J3: =YEAR(A3)&"-"&TEXT(MONTH(A3),"00") -> 2022-03
A4: 44638 | B4: 44656 | C4: =Table1[[#This Row],[Check-out Date]]-Table1[[#This Row],[Check-in Date]] -> 18 | D4: B303 | E4: Emmeline Page | F4: 1298 | G4: =Table1[[#This Row],[FULL AMOUNT usd]]*20 -> 25960 | H4: =F4*0.2 -> 259.6 | I4: Airbnb | J4: =YEAR(A4)&"-"&TEXT(MONTH(A4),"00") -> 2022-03
A5: 44644 | B5: 44660 | C5: =Table1[[#This Row],[Check-out Date]]-Table1[[#This Row],[Check-in Date]] -> 16 | D5: A302 | E5: Stephen Mack | F5: 857.89 | G5: =Table1[[#This Row],[FULL AMOUNT usd]]*20 -> 17157.8 | H5: =F5*0.2 -> 171.578 | I5: Airbnb | J5: =YEAR(A5)&"-"&TEXT(MONTH(A5),"00") -> 2022-03
A6: 44645 | B6: 44647 | C6: =Table1[[#This Row],[Check-out Date]]-Table1[[#This Row],[Check-in Date]] -> 2 | D6: A302 | E6: Jhonatham Cummings | F6: 291.54 | G6: =Table1[[#This Row],[FULL AMOUNT usd]]*20 -> 5830.8 | H6: =F6*0.2 -> 58.308 | I6: Airbnb | J6: =YEAR(A6)&"-"&TEXT(MONTH(A6),"00") -> 2022-03
A7: 44652 | B7: 44656 | C7: =Table1[[#This Row],[Check-out Date]]-Table1[[#This Row],[Check-in Date]] -> 4 | D7: A302 | E7: Ian Downie | F7: 448 | G7: =Table1[[#This Row],[FULL AMOUNT usd]]*20 -> 8960 | H7: =F7*0.2 -> 89.6 | I7: Booking | J7: =YEAR(A7)&"-"&TEXT(MONTH(A7),"00") -> 2022-04
A8: 44659 | B8: 44661 | C8: =Table1[[#This Row],[Check-out Date]]-Table1[[#This Row],[Check-in Date]] -> 2 | D8: B303 | E8: Ryan Walsh | F8: 268.94 | G8: =Table1[[#This Row],[FULL AMOUNT usd]]*20 -> 5378.8 | H8: =F8*0.2 -> 53.788 | I8: Airbnb | J8: =YEAR(A8)&"-"&TEXT(MONTH(A8),"00") -> 2022-04
A9: 44661 | B9: 44666 | C9: =Table1[[#This Row],[Check-out Date]]-Table1[[#This Row],[Check-in Date]] -> 5 | D9: A302 | E9: Misty Erkkila | F9: 627.15 | G9: =Table1[[#This Row],[FULL AMOUNT usd]]*20 -> 12543 | H9: =F9*0.2 -> 125.43 | I9: Airbnb | J9: =YEAR(A9)&"-"&TEXT(MONTH(A9),"00") -> 2022-04
A10: 44664 | B10: 44667 | C10: =Table1[[#This Row],[Check-out Date]]-Table1[[#This Row],[Check-in Date]] -> 3 | D10: B303 | E10: Taran Parmar | F10: 335.61 | G10: =Table1[[#This Row],[FULL AMOUNT usd]]*20 -> 6712.2 | H10: =F10*0.2 -> 67.122 | I10: Airbnb | J10: =YEAR(A10)&"-"&TEXT(MONTH(A10),"00") -> 2022-04
A11: 44667 | B11: 44670 | C11: =Table1[[#This Row],[Check-out Date]]-Table1[[#This Row],[Check-in Date]] -> 3 | D11: A302 | E11: Taran Parmar | F11: 360 | G11: =Table1[[#This Row],[FULL AMOUNT usd]]*20 -> 7200 | H11: =F11*0.2 -> 72 | I11: Airbnb | J11: =YEAR(A11)&"-"&TEXT(MONTH(A11),"00") -> 2022-04
A12: 44668 | B12: 44681 | C12: =Table1[[#This Row],[Check-out Date]]-Table1[[#This Row],[Check-in Date]] -> 13 | D12: B303 | E12: Sergey Kulagin | F12: 1449.39 | G12: =Table1[[#This Row],[FULL AMOUNT usd]]*20 -> 28987.8 | H12: =F12*0.2 -> 289.878 | I12: Airbnb | J12: =YEAR(A12)&"-"&TEXT(MONTH(A12),"00") -> 2022-04
A13: 44673 | B13: 44680 | C13: =Table1[[#This Row],[Check-out Date]]-Table1[[#This Row],[Check-in Date]] -> 7 | D13: A302 | E13: Hilary Hoover | F13: 996.66 | G13: =Table1[[#This Row],[FULL AMOUNT usd]]*20 -> 19933.2 | H13: =F13*0.2 -> 199.332 | I13: Airbnb | J13: =YEAR(A13)&"-"&TEXT(MONTH(A13),"00") -> 2022-04
... A34: 44786 | B34: 44790 | C34: =Table1[[#This Row],[Check-out Date]]-Table1[[#This Row],[Check-in Date]] -> 4 | D34: A302 | E34: Nikia Leamire | F34: 452.11 | G34: =Table1[[#This Row],[FULL AMOUNT usd]]*20 -> 9042.2 | H34: =F34*0.2 -> 90.422 | I34: Airbnb | J34: =YEAR(A34)&"-"&TEXT(MONTH(A34),"00") -> 2022-08
A35: 44789 | B35: 44796 | C35: =Table1[[#This Row],[Check-out Date]]-Table1[[#This Row],[Check-in Date]] -> 7 | D35: C301 | F35: 631.62 | G35: =Table1[[#This Row],[FULL AMOUNT usd]]*20 -> 12632.4 | H35: =F35*0.2 -> 126.324 | I35: Airbnb | J35: =YEAR(A35)&"-"&TEXT(MONTH(A35),"00") -> 2022-08
A36: 44797 | B36: 44802 | C36: =Table1[[#This Row],[Check-out Date]]-Table1[[#This Row],[Check-in Date]] -> 5 | D36: C301 | E36: Alexis Dubourdieu | F36: 171.42 | G36: =Table1[[#This Row],[FULL AMOUNT usd]]*20 -> 3428.4 | H36: =F36*0.2 -> 34.284 | I36: Direct Reservation | J36: =YEAR(A36)&"-"&TEXT(MONTH(A36),"00") -> 2022-08
A37: 44797 | B37: 44802 | C37: =Table1[[#This Row],[Check-out Date]]-Table1[[#This Row],[Check-in Date]] -> 5 | D37: C301 | F37: 171.42 | G37: =Table1[[#This Row],[FULL AMOUNT usd]]*20 -> 3428.4 | H37: =F37*0.2 -> 34.284 | I37: Airbnb | J37: =YEAR(A37)&"-"&TEXT(MONTH(A37),"00") -> 2022-08
A38: 44798 | B38: 44803 | C38: =Table1[[#This Row],[Check-out Date]]-Table1[[#This Row],[Check-in Date]] -> 5 | D38: B303 | E38: Matthew Tatum | F38: 269.51 | G38: =Table1[[#This Row],[FULL AMOUNT usd]]*20 -> 5390.2 | H38: =F38*0.2 -> 53.902 | I38: Airbnb | J38: =YEAR(A38)&"-"&TEXT(MONTH(A38),"00") -> 2022-08
A39: 44842 | B39: 44846 | C39: =Table1[[#This Row],[Check-out Date]]-Table1[[#This Row],[Check-in Date]] -> 4 | D39: A302 | E39: Greg Chapple | F39: 222 | G39: =Table1[[#This Row],[FULL AMOUNT usd]]*20 -> 4440 | H39: =F39*0.2 -> 44.4 | I39: Expedia | J39: =YEAR(A39)&"-"&TEXT(MONTH(A39),"00") -> 2022-10
A40: 44852 | B40: 44855 | C40: =Table1[[#This Row],[Check-out Date]]-Table1[[#This Row],[Check-in Date]] -> 3 | D40: A302 | E40: Jennifer Myers | F40: 321 | G40: =Table1[[#This Row],[FULL AMOUNT usd]]*20 -> 6420 | H40: =F40*0.2 -> 64.2 | I40: Airbnb | J40: =YEAR(A40)&"-"&TEXT(MONTH(A40),"00") -> 2022-10
A41: 44864 | B41: 44867 | C41: =Table1[[#This Row],[Check-out Date]]-Table1[[#This Row],[Check-in Date]] -> 3 | D41: A302 | E41: George White | F41: 357 | G41: =Table1[[#This Row],[FULL AMOUNT usd]]*20 -> 7140 | H41: =F41*0.2 -> 71.4 | I41: Airbnb | J41: =YEAR(A41)&"-"&TEXT(MONTH(A41),"00") -> 2022-10
A42: 44868 | B42: 44876 | C42: =Table1[[#This Row],[Check-out Date]]-Table1[[#This Row],[Check-in Date]] -> 8 | D42: A302 | E42: Yadira Barrera | F42: 918 | G42: =Table1[[#This Row],[FULL AMOUNT usd]]*20 -> 18360 | H42: =F42*0.2 -> 183.6 | I42: Airbnb | J42: =YEAR(A42)&"-"&TEXT(MONTH(A42),"00") -> 2022-11
A43: 44873 | B43: 44877 | C43: =Table1[[#This Row],[Check-out Date]]-Table1[[#This Row],[Check-in Date]] -> 4 | D43: C301 | E43: Cossette Haddock | F43: 291.54 | G43: =Table1[[#This Row],[FULL AMOUNT usd]]*20 -> 5830.8 | H43: =F43*0.2 -> 58.308 | I43: Expedia | J43: =YEAR(A43)&"-"&TEXT(MONTH(A43),"00") -> 2022-11
A44: 44873 | B44: 44877 | C44: =Table1[[#This Row],[Check-out Date]]-Table1[[#This Row],[Check-in Date]] -> 4 | D44: C301 | F44: 291.54 | G44: =Table1[[#This Row],[FULL AMOUNT usd]]*20 -> 5830.8 | H44: =F44*0.2 -> 58.308 | I44: Airbnb | J44: =YEAR(A44)&"-"&TEXT(MONTH(A44),"00") -> 2022-11
A45: 44876 | B45: 44881 | C45: =Table1[[#This Row],[Check-out Date]]-Table1[[#This Row],[Check-in Date]] -> 5 | D45: A302 | E45: Johnny Hernandez | F45: 621.5 | G45: =Table1[[#This Row],[FULL AMOUNT usd]]*20 -> 12430 | H45: =F45*0.2 -> 124.3 | I45: Airbnb | J45: =YEAR(A45)&"-"&TEXT(MONTH(A45),"00") -> 2022-11
A46: 44878 | B46: 44884 | C46: =Table1[[#This Row],[Check-out Date]]-Table1[[#This Row],[Check-in Date]] -> 6 | D46: B303 | E46: Aniket Sharma | F46: 615 | G46: =Table1[[#This Row],[FULL AMOUNT usd]]*20 -> 12300 | H46: =F46*0.2 -> 123 | I46: Airbnb | J46: =YEAR(A46)&"-"&TEXT(MONTH(A46),"00") -> 2022-11
A47: 44885 | B47: 44889 | C47: =Table1[[#This Row],[Check-out Date]]-Table1[[#This Row],[Check-in Date]] -> 4 | D47: A302 | E47: Shane Finkelstein | F47: 337.65 | G47: =Table1[[#This Row],[FULL AMOUNT usd]]*20 -> 6753 | H47: =F47*0.2 -> 67.53 | I47: Expedia | J47: =YEAR(A47)&"-"&TEXT(MONTH(A47),"00") -> 2022-11
A48: 44888 | B48: 44893 | C48: =Table1[[#This Row],[Check-out Date]]-Table1[[#This Row],[Check-in Date]] -> 5 | D48: A302 | E48: Pre Knechia | F48: 211 | G48: =Table1[[#This Row],[FULL AMOUNT usd]]*20 -> 4220 | H48: =F48*0.2 -> 42.2 | I48: Expedia | J48: =YEAR(A48)&"-"&TEXT(MONTH(A48),"00") -> 2022-11
A49: 44895 | B49: 44899 | C49: =Table1[[#This Row],[Check-out Date]]-Table1[[#This Row],[Check-in Date]] -> 4 | D49: A302 | E49: Brian Concah | F49: 378.33 | G49: =Table1[[#This Row],[FULL AMOUNT usd]]*20 -> 7566.6 | H49: =F49*0.2 -> 75.666 | I49: Airbnb | J49: =YEAR(A49)&"-"&TEXT(MONTH(A49),"00") -> 2022-11
A50: 44898 | B50: 44902 | C50: =Table1[[#This Row],[Check-out Date]]-Table1[[#This Row],[Check-in Date]] -> 4 | D50: A302 | E50: Felix Bostel | F50: 258.55 | G50: =Table1[[#This Row],[FULL AMOUNT usd]]*20 -> 5171 | H50: =F50*0.2 -> 51.71 | I50: Expedia | J50: =YEAR(A50)&"-"&TEXT(MONTH(A50),"00") -> 2022-12
A51: 44899 | B51: 44903 | C51: =Table1[[#This Row],[Check-out Date]]-Table1[[#This Row],[Check-in Date]] -> 4 | D51: B303 | E51: Maya Dadez | F51: 378.33 | G51: =Table1[[#This Row],[FULL AMOUNT usd]]*20 -> 7566.6 | H51: =F51*0.2 -> 75.666 | I51: Expedia | J51: =YEAR(A51)&"-"&TEXT(MONTH(A51),"00") -> 2022-12
A52: 44903 | B52: 44906 | C52: =Table1[[#This Row],[Check-out Date]]-Table1[[#This Row],[Check-in Date]] -> 3 | D52: B303 | E52: Adrien Green | F52: 300.7 | G52: =Table1[[#This Row],[FULL AMOUNT usd]]*20 -> 6014 | H52: =F52*0.2 -> 60.14 | I52: Direct Reservation | J52: =YEAR(A52)&"-"&TEXT(MONTH(A52),"00") -> 2022-12
A53: 44915 | B53: 44920 | C53: =Table1[[#This Row],[Check-out Date]]-Table1[[#This Row],[Check-in Date]] -> 5 | D53: B303 | E53: Akshay Pimprikar | F53: 523.76 | G53: =Table1[[#This Row],[FULL AMOUNT usd]]*20 -> 10475.2 | H53: =F53*0.2 -> 104.752 | I53: Airbnb | J53: =YEAR(A53)&"-"&TEXT(MONTH(A53),"00") -> 2022-12
A54: 44916 | B54: 44920 | C54: =Table1[[#This Row],[Check-out Date]]-Table1[[#This Row],[Check-in Date]] -> 4 | D54: A302 | E54: Sameer Singh | F54: 272.11 | G54: =Table1[[#This Row],[FULL AMOUNT usd]]*20 -> 5442.2 | H54: =F54*0.2 -> 54.422 | I54: Airbnb | J54: =YEAR(A54)&"-"&TEXT(MONTH(A54),"00") -> 2022-12
A55: 44920 | B55: 44925 | C55: =Table1[[#This Row],[Check-out Date]]-Table1[[#This Row],[Check-in Date]] -> 5 | D55: A302 | E55: Karen G | F55: 1183.68 | G55: =Table1[[#This Row],[FULL AMOUNT usd]]*20 -> 23673.6 | H55: =F55*0.2 -> 236.736 | I55: Airbnb | J55: =YEAR(A55)&"-"&TEXT(MONTH(A55),"00") -> 2022-12
A56: 44920 | B56: 44922 | C56: =Table1[[#This Row],[Check-out Date]]-Table1[[#This Row],[Check-in Date]] -> 2 | D56: B303 | E56: Luis Lopez | F56: 472.02 | G56: =Table1[[#This Row],[FULL AMOUNT usd]]*20 -> 9440.4 | H56: =F56*0.2 -> 94.404 | I56: Airbnb | J56: =YEAR(A56)&"-"&TEXT(MONTH(A56),"00") -> 2022-12
... A58: 44923 | B58: 44925 | C58: =Table1[[#This Row],[Check-out Date]]-Table1[[#This Row],[Check-in Date]] -> 2 | D58: C301 | E58: Kerry Bole | F58: 110 | G58: =Table1[[#This Row],[FULL AMOUNT usd]]*20 -> 2200 | H58: =F58*0.2 -> 22 | I58: Airbnb | J58: =YEAR(A58)&"-"&TEXT(MONTH(A58),"00") -> 2022-12
A59: 44923 | B59: 44925 | C59: =Table1[[#This Row],[Check-out Date]]-Table1[[#This Row],[Check-in Date]] -> 2 | D59: C301 | F59: 160 | G59: =Table1[[#This Row],[FULL AMOUNT usd]]*20 -> 3200 | H59: =F59*0.2 -> 32 | I59: Airbnb | J59: =YEAR(A59)&"-"&TEXT(MONTH(A59),"00") -> 2022-12
A60: 44923 | B60: 44925 | C60: =Table1[[#This Row],[Check-out Date]]-Table1[[#This Row],[Check-in Date]] -> 2 | D60: C301 | F60: 110 | G60: =Table1[[#This Row],[FULL AMOUNT usd]]*20 -> 2200 | H60: =F60*0.2 -> 22 | I60: Airbnb | J60: =YEAR(A60)&"-"&TEXT(MONTH(A60),"00") -> 2022-12
A61: 44924 | B61: 44929 | C61: =Table1[[#This Row],[Check-out Date]]-Table1[[#This Row],[Check-in Date]] -> 5 | D61: B303 | E61: Jerrod Noble | F61: 2043.04 | G61: =Table1[[#This Row],[FULL AMOUNT usd]]*20 -> 40860.8 | H61: =F61*0.2 -> 408.608 | I61: Expedia | J61: =YEAR(A61)&"-"&TEXT(MONTH(A61),"00") -> 2022-12
...

Sheet EXPENSES
A1: DATE | B1: SERVICE | C1: APT | D1: COST $ | E1: TYPE | F1: MONTH
A2: 44576 | B2: Fridge manteinance | C2: B303 | D2: 1658.98 | E2: =IF(OR(C2="A302", C2="B303", C2="C301"), "Direct", "Shared") -> Direct | F2: =YEAR(A2)&"-"&TEXT(MONTH(A2),"00") -> 2022-01
A3: 44576 | B3: Plumber for changing water pump | C3: B303 | D3: 600 | E3: =IF(OR(C3="A302", C3="B303", C3="C301"), "Direct", "Shared") -> Direct | F3: =YEAR(A3)&"-"&TEXT(MONTH(A3),"00") -> 2022-01
A4: 44576 | B4: Roof pool cleaning + chlorine | C4: B303 | D4: 450 | E4: =IF(OR(C4="A302", C4="B303", C4="C301"), "Direct", "Shared") -> Direct | F4: =YEAR(A4)&"-"&TEXT(MONTH(A4),"00") -> 2022-01
A5: 44576 | B5: Lock change entrance door | C5: B303 | D5: 1200 | E5: =IF(OR(C5="A302", C5="B303", C5="C301"), "Direct", "Shared") -> Direct | F5: =YEAR(A5)&"-"&TEXT(MONTH(A5),"00") -> 2022-01
A6: 44576 | B6: Deadbolt instalation | C6: B303 | D6: 500 | E6: =IF(OR(C6="A302", C6="B303", C6="C301"), "Direct", "Shared") -> Direct | F6: =YEAR(A6)&"-"&TEXT(MONTH(A6),"00") -> 2022-01
A7: 44576 | B7: Internet contract | C7: B303 | D7: 5000 | E7: =IF(OR(C7="A302", C7="B303", C7="C301"), "Direct", "Shared") -> Direct | F7: =YEAR(A7)&"-"&TEXT(MONTH(A7),"00") -> 2022-01
A8: 44576 | B8: Table games (Catan, Bycycle cards, Sequence) | C8: Overhead | D8: 1870 | E8: =IF(OR(C8="A302", C8="B303", C8="C301"), "Direct", "Shared") -> Shared | F8: =YEAR(A8)&"-"&TEXT(MONTH(A8),"00") -> 2022-01
A9: 44576 | B9: Dishwasher | C9: B303 | D9: 600 | E9: =IF(OR(C9="A302", C9="B303", C9="C301"), "Direct", "Shared") -> Direct | F9: =YEAR(A9)&"-"&TEXT(MONTH(A9),"00") -> 2022-01
A10: 44579 | B10: Copies documents | C10: Overhead | D10: 18 | E10: =IF(OR(C10="A302", C10="B303", C10="C301"), "Direct", "Shared") -> Shared | F10: =YEAR(A10)&"-"&TEXT(MONTH(A10),"00") -> 2022-01
A11: 44581 | B11: Sliding door fixed (no paint) | C11: B303 | D11: 1400 | E11: =IF(OR(C11="A302", C11="B303", C11="C301"), "Direct", "Shared") -> Direct | F11: =YEAR(A11)&"-"&TEXT(MONTH(A11),"00") -> 2022-01
A12: 44581 | B12: Front door fixed and paint | C12: B303 | D12: 2800 | E12: =IF(OR(C12="A302", C12="B303", C12="C301"), "Direct", "Shared") -> Direct | F12: =YEAR(A12)&"-"&TEXT(MONTH(A12),"00") -> 2022-01
A13: 44581 | B13: Paint 2 sliding doors, door upstairs, windows | C13: B303 | D13: 3800 | E13: =IF(OR(C13="A302", C13="B303", C13="C301"), "Direct", "Shared") -> Direct | F13: =YEAR(A13)&"-"&TEXT(MONTH(A13),"00") -> 2022-01
... A1561: 46160 | B1561: Cleaning 2 bedrooms | C1561: A302 | D1561: 2000 | E1561: =IF(OR(C1561="A302", C1561="B303", C1561="C301"), "Direct", "Shared") -> Direct | F1561: =YEAR(A1561)&"-"&TEXT(MONTH(A1561),"00") -> 2026-05

Sheet Reference_Nights
A1: Month | B1: Apt | C1: Days_in_month | D1: Unavailable_days | E1: Available_nights
A2: 2022-03 | B2: A302 | C2: =DAY(DATE(VALUE(LEFT(A2,4)),VALUE(RIGHT(A2,2))+1,1)-1) -> 31 | D2: 3 | E2: =Reference_Nights[[#This Row],[Days_in_month]]-Reference_Nights[[#This Row],[Unavailable_days]] -> 28
A3: 2022-03 | B3: B303 | C3: =DAY(DATE(VALUE(LEFT(A3,4)),VALUE(RIGHT(A3,2))+1,1)-1) -> 31 | D3: 3 | E3: =Reference_Nights[[#This Row],[Days_in_month]]-Reference_Nights[[#This Row],[Unavailable_days]] -> 28
A4: 2022-03 | B4: C301 | C4: =DAY(DATE(VALUE(LEFT(A4,4)),VALUE(RIGHT(A4,2))+1,1)-1) -> 31 | D4: 3 | E4: =Reference_Nights[[#This Row],[Days_in_month]]-Reference_Nights[[#This Row],[Unavailable_days]] -> 28
A5: 2022-04 | B5: A302 | C5: =DAY(DATE(VALUE(LEFT(A5,4)),VALUE(RIGHT(A5,2))+1,1)-1) -> 30 | D5: 3 | E5: =Reference_Nights[[#This Row],[Days_in_month]]-Reference_Nights[[#This Row],[Unavailable_days]] -> 27
A6: 2022-04 | B6: B303 | C6: =DAY(DATE(VALUE(LEFT(A6,4)),VALUE(RIGHT(A6,2))+1,1)-1) -> 30 | D6: 3 | E6: =Reference_Nights[[#This Row],[Days_in_month]]-Reference_Nights[[#This Row],[Unavailable_days]] -> 27
A7: 2022-04 | B7: C301 | C7: =DAY(DATE(VALUE(LEFT(A7,4)),VALUE(RIGHT(A7,2))+1,1)-1) -> 30 | D7: 3 | E7: =Reference_Nights[[#This Row],[Days_in_month]]-Reference_Nights[[#This Row],[Unavailable_days]] -> 27
A8: 2022-05 | B8: A302 | C8: =DAY(DATE(VALUE(LEFT(A8,4)),VALUE(RIGHT(A8,2))+1,1)-1) -> 31 | D8: 3 | E8: =Reference_Nights[[#This Row],[Days_in_month]]-Reference_Nights[[#This Row],[Unavailable_days]] -> 28
A9: 2022-05 | B9: B303 | C9: =DAY(DATE(VALUE(LEFT(A9,4)),VALUE(RIGHT(A9,2))+1,1)-1) -> 31 | D9: 3 | E9: =Reference_Nights[[#This Row],[Days_in_month]]-Reference_Nights[[#This Row],[Unavailable_days]] -> 28
A10: 2022-05 | B10: C301 | C10: =DAY(DATE(VALUE(LEFT(A10,4)),VALUE(RIGHT(A10,2))+1,1)-1) -> 31 | D10: 3 | E10: =Reference_Nights[[#This Row],[Days_in_month]]-Reference_Nights[[#This Row],[Unavailable_days]] -> 28
A11: 2022-06 | B11: A302 | C11: =DAY(DATE(VALUE(LEFT(A11,4)),VALUE(RIGHT(A11,2))+1,1)-1) -> 30 | D11: 3 | E11: =Reference_Nights[[#This Row],[Days_in_month]]-Reference_Nights[[#This Row],[Unavailable_days]] -> 27
A12: 2022-06 | B12: B303 | C12: =DAY(DATE(VALUE(LEFT(A12,4)),VALUE(RIGHT(A12,2))+1,1)-1) -> 30 | D12: 3 | E12: =Reference_Nights[[#This Row],[Days_in_month]]-Reference_Nights[[#This Row],[Unavailable_days]] -> 27
A13: 2022-06 | B13: C301 | C13: =DAY(DATE(VALUE(LEFT(A13,4)),VALUE(RIGHT(A13,2))+1,1)-1) -> 30 | D13: 3 | E13: =Reference_Nights[[#This Row],[Days_in_month]]-Reference_Nights[[#This Row],[Unavailable_days]] -> 27
... A154: 2026-05 | B154: C301 | C154: =DAY(DATE(VALUE(LEFT(A154,4)),VALUE(RIGHT(A154,2))+1,1)-1) -> 31 | D154: 3 | E154: =Reference_Nights[[#This Row],[Days_in_month]]-Reference_Nights[[#This Row],[Unavailable_days]] -> 28

Sheet Data_Consolidado
A1: Month | B1: Apt | C1: Income | D1: Booked_Nights | E1: Exp_Direct | F1: Pct_Income | G1: Shared_Total | H1: Shared_Assigned | I1: Total_Exp | J1: Profit_or_Loss | K1: Margin% | L1: Available _Nights | M1: Occupancy_Rate | N1: Avg_Daily_Rate | O1: Rev_per_Av_Night | P1: Expense_Ratio%
A2: 2022-01 | B2: A302 | C2: =SUMIFS(Table1[FULL AMOUNT mxn pesos], Table1[Month], A2, Table1[APARTMENT], B2) -> 0 | D2: =SUMIFS(INCOME!C:C, INCOME!D:D, Table2[[#This Row],[Apt]], INCOME!J:J, Table2[[#This Row],[Month]]) -> 0 | E2: =SUMIFS(EXPENSES!$D:$D, EXPENSES!$C:$C, B2, EXPENSES!$F:$F, A2, EXPENSES!$E:$E, "Direct") -> 3464.76 | F2: =IF(C2=0,0,C2/SUMIF(A:A,A2,C:C)) -> 0 | G2: =SUMIFS(EXPENSES!D:D, EXPENSES!F:F, Data_Consolidado!A2, EXPENSES!E:E, "Shared") -> 5188 | H2: =Table2[[#This Row],[Shared_Total]]/2 -> 2594 | I2: =E2+H2 -> 6058.76 | J2: =C2-I2 -> -6058.76 | K2: =IF(C2=0, "-", (J2/C2)) -> - | L2: =SUMIFS(Reference_Nights[[#All],[Available_nights]], Reference_Nights[[#All],[Month]], Table2[[#This Row],[Month]], Reference_Nights[[#All],[Apt]], Table2[[#This Row],[Apt]]) -> 0 | M2: =IF(Table2[[#This Row],[Available _Nights]]=0, 0, Table2[[#This Row],[Booked_Nights]]/Table2[[#This Row],[Available _Nights]]) -> 0 | N2: =IF(Table2[[#This Row],[Booked_Nights]]=0, 0, Table2[[#This Row],[Income]]/Table2[[#This Row],[Booked_Nights]]) -> 0 | O2: =IF(L2=0,0, Table2[[#This Row],[Income]]/Table2[[#This Row],[Available _Nights]]) -> 0 | P2: =IF(Table2[[#This Row],[Income]]=0,0,Table2[[#This Row],[Total_Exp]]/Table2[[#This Row],[Income]]) -> 0
A3: 2022-01 | B3: B303 | C3: =SUMIFS(Table1[FULL AMOUNT mxn pesos], Table1[Month], A3, Table1[APARTMENT], B3) -> 0 | D3: =SUMIFS(INCOME!C:C, INCOME!D:D, Table2[[#This Row],[Apt]], INCOME!J:J, Table2[[#This Row],[Month]]) -> 0 | E3: =SUMIFS(EXPENSES!$D:$D, EXPENSES!$C:$C, B3, EXPENSES!$F:$F, A3, EXPENSES!$E:$E, "Direct") -> 39110.72 | F3: =IF(C3=0,0,C3/SUMIF(A:A,A3,C:C)) -> 0 | G3: =SUMIFS(EXPENSES!D:D, EXPENSES!F:F, Data_Consolidado!A3, EXPENSES!E:E, "Shared") -> 5188 | H3: =Table2[[#This Row],[Shared_Total]]/2 -> 2594 | I3: =E3+H3 -> 41704.72 | J3: =C3-I3 -> -41704.72 | K3: =IF(C3=0, "-", (J3/C3)) -> - | L3: =SUMIFS(Reference_Nights[[#All],[Available_nights]], Reference_Nights[[#All],[Month]], Table2[[#This Row],[Month]], Reference_Nights[[#All],[Apt]], Table2[[#This Row],[Apt]]) -> 0 | M3: =IF(Table2[[#This Row],[Available _Nights]]=0, 0, Table2[[#This Row],[Booked_Nights]]/Table2[[#This Row],[Available _Nights]]) -> 0 | N3: =IF(Table2[[#This Row],[Booked_Nights]]=0, 0, Table2[[#This Row],[Income]]/Table2[[#This Row],[Booked_Nights]]) -> 0 | O3: =IF(L3=0,0, Table2[[#This Row],[Income]]/Table2[[#This Row],[Available _Nights]]) -> 0 | P3: =IF(Table2[[#This Row],[Income]]=0,0,Table2[[#This Row],[Total_Exp]]/Table2[[#This Row],[Income]]) -> 0
A4: 2022-02 | B4: A302 | C4: =SUMIFS(Table1[FULL AMOUNT mxn pesos], Table1[Month], A4, Table1[APARTMENT], B4) -> 0 | D4: =SUMIFS(INCOME!C:C, INCOME!D:D, Table2[[#This Row],[Apt]], INCOME!J:J, Table2[[#This Row],[Month]]) -> 0 | E4: =SUMIFS(EXPENSES!$D:$D, EXPENSES!$C:$C, B4, EXPENSES!$F:$F, A4, EXPENSES!$E:$E, "Direct") -> 9560 | F4: =IF(C4=0,0,C4/SUMIF(A:A,A4,C:C)) -> 0 | G4: =SUMIFS(EXPENSES!D:D, EXPENSES!F:F, Data_Consolidado!A4, EXPENSES!E:E, "Shared") -> 1240 | H4: =Table2[[#This Row],[Shared_Total]]/2 -> 620 | I4: =E4+H4 -> 10180 | J4: =C4-I4 -> -10180 | K4: =IF(C4=0, "-", (J4/C4)) -> - | L4: =SUMIFS(Reference_Nights[[#All],[Available_nights]], Reference_Nights[[#All],[Month]], Table2[[#This Row],[Month]], Reference_Nights[[#All],[Apt]], Table2[[#This Row],[Apt]]) -> 0 | M4: =IF(Table2[[#This Row],[Available _Nights]]=0, 0, Table2[[#This Row],[Booked_Nights]]/Table2[[#This Row],[Available _Nights]]) -> 0 | N4: =IF(Table2[[#This Row],[Booked_Nights]]=0, 0, Table2[[#This Row],[Income]]/Table2[[#This Row],[Booked_Nights]]) -> 0 | O4: =IF(L4=0,0, Table2[[#This Row],[Income]]/Table2[[#This Row],[Available _Nights]]) -> 0 | P4: =IF(Table2[[#This Row],[Income]]=0,0,Table2[[#This Row],[Total_Exp]]/Table2[[#This Row],[Income]]) -> 0
A5: 2022-02 | B5: B303 | C5: =SUMIFS(Table1[FULL AMOUNT mxn pesos], Table1[Month], A5, Table1[APARTMENT], B5) -> 0 | D5: =SUMIFS(INCOME!C:C, INCOME!D:D, Table2[[#This Row],[Apt]], INCOME!J:J, Table2[[#This Row],[Month]]) -> 0 | E5: =SUMIFS(EXPENSES!$D:$D, EXPENSES!$C:$C, B5, EXPENSES!$F:$F, A5, EXPENSES!$E:$E, "Direct") -> 26307 | F5: =IF(C5=0,0,C5/SUMIF(A:A,A5,C:C)) -> 0 | G5: =SUMIFS(EXPENSES!D:D, EXPENSES!F:F, Data_Consolidado!A5, EXPENSES!E:E, "Shared") -> 1240 | H5: =Table2[[#This Row],[Shared_Total]]/2 -> 620 | I5: =E5+H5 -> 26927 | J5: =C5-I5 -> -26927 | K5: =IF(C5=0, "-", (J5/C5)) -> - | L5: =SUMIFS(Reference_Nights[[#All],[Available_nights]], Reference_Nights[[#All],[Month]], Table2[[#This Row],[Month]], Reference_Nights[[#All],[Apt]], Table2[[#This Row],[Apt]]) -> 0 | M5: =IF(Table2[[#This Row],[Available _Nights]]=0, 0, Table2[[#This Row],[Booked_Nights]]/Table2[[#This Row],[Available _Nights]]) -> 0 | N5: =IF(Table2[[#This Row],[Booked_Nights]]=0, 0, Table2[[#This Row],[Income]]/Table2[[#This Row],[Booked_Nights]]) -> 0 | O5: =IF(L5=0,0, Table2[[#This Row],[Income]]/Table2[[#This Row],[Available _Nights]]) -> 0 | P5: =IF(Table2[[#This Row],[Income]]=0,0,Table2[[#This Row],[Total_Exp]]/Table2[[#This Row],[Income]]) -> 0
A6: 2022-03 | B6: A302 | C6: =SUMIFS(Table1[FULL AMOUNT mxn pesos], Table1[Month], A6, Table1[APARTMENT], B6) -> 33655.8 | D6: =SUMIFS(INCOME!C:C, INCOME!D:D, Table2[[#This Row],[Apt]], INCOME!J:J, Table2[[#This Row],[Month]]) -> 23 | E6: =SUMIFS(EXPENSES!$D:$D, EXPENSES!$C:$C, B6, EXPENSES!$F:$F, A6, EXPENSES!$E:$E, "Direct") -> 5533 | F6: =IF(C6=0,0,C6/SUMIF(A:A,A6,C:C)) -> 0.50731065 | G6: =SUMIFS(EXPENSES!D:D, EXPENSES!F:F, Data_Consolidado!A6, EXPENSES!E:E, "Shared") -> 7565.5 | H6: =G6*F6 -> 3838.0587 | I6: =E6+H6 -> 9371.0587 | J6: =C6-I6 -> 24284.741 | K6: =IF(C6=0, "-", (J6/C6)) -> 0.72156185 | L6: =SUMIFS(Reference_Nights[[#All],[Available_nights]], Reference_Nights[[#All],[Month]], Table2[[#This Row],[Month]], Reference_Nights[[#All],[Apt]], Table2[[#This Row],[Apt]]) -> 28 | M6: =IF(Table2[[#This Row],[Available _Nights]]=0, 0, Table2[[#This Row],[Booked_Nights]]/Table2[[#This Row],[Available _Nights]]) -> 0.82142857 | N6: =IF(Table2[[#This Row],[Booked_Nights]]=0, 0, Table2[[#This Row],[Income]]/Table2[[#This Row],[Booked_Nights]]) -> 1463.2957 | O6: =IF(L6=0,0, Table2[[#This Row],[Income]]/Table2[[#This Row],[Available _Nights]]) -> 1201.9929 | P6: =IF(Table2[[#This Row],[Income]]=0,0,Table2[[#This Row],[Total_Exp]]/Table2[[#This Row],[Income]]) -> 0.27843815
A7: 2022-03 | B7: B303 | C7: =SUMIFS(Table1[FULL AMOUNT mxn pesos], Table1[Month], A7, Table1[APARTMENT], B7) -> 32685.8 | D7: =SUMIFS(INCOME!C:C, INCOME!D:D, Table2[[#This Row],[Apt]], INCOME!J:J, Table2[[#This Row],[Month]]) -> 21 | E7: =SUMIFS(EXPENSES!$D:$D, EXPENSES!$C:$C, B7, EXPENSES!$F:$F, A7, EXPENSES!$E:$E, "Direct") -> 16096.75 | F7: =IF(C7=0,0,C7/SUMIF(A:A,A7,C:C)) -> 0.49268935 | G7: =SUMIFS(EXPENSES!D:D, EXPENSES!F:F, Data_Consolidado!A7, EXPENSES!E:E, "Shared") -> 7565.5 | H7: =G7*F7 -> 3727.4413 | I7: =E7+H7 -> 19824.191 | J7: =C7-I7 -> 12861.609 | K7: =IF(C7=0, "-", (J7/C7)) -> 0.39349224 | L7: =SUMIFS(Reference_Nights[[#All],[Available_nights]], Reference_Nights[[#All],[Month]], Table2[[#This Row],[Month]], Reference_Nights[[#All],[Apt]], Table2[[#This Row],[Apt]]) -> 28 | M7: =IF(Table2[[#This Row],[Available _Nights]]=0, 0, Table2[[#This Row],[Booked_Nights]]/Table2[[#This Row],[Available _Nights]]) -> 0.75 | N7: =IF(Table2[[#This Row],[Booked_Nights]]=0, 0, Table2[[#This Row],[Income]]/Table2[[#This Row],[Booked_Nights]]) -> 1556.4667 | O7: =IF(L7=0,0, Table2[[#This Row],[Income]]/Table2[[#This Row],[Available _Nights]]) -> 1167.35 | P7: =IF(Table2[[#This Row],[Income]]=0,0,Table2[[#This Row],[Total_Exp]]/Table2[[#This Row],[Income]]) -> 0.60650776
A8: 2022-04 | B8: A302 | C8: =SUMIFS(Table1[FULL AMOUNT mxn pesos], Table1[Month], A8, Table1[APARTMENT], B8) -> 68562.6 | D8: =SUMIFS(INCOME!C:C, INCOME!D:D, Table2[[#This Row],[Apt]], INCOME!J:J, Table2[[#This Row],[Month]]) -> 26 | E8: =SUMIFS(EXPENSES!$D:$D, EXPENSES!$C:$C, B8, EXPENSES!$F:$F, A8, EXPENSES!$E:$E, "Direct") -> 11030 | F8: =IF(C8=0,0,C8/SUMIF(A:A,A8,C:C)) -> 0.58247246 | G8: =SUMIFS(EXPENSES!D:D, EXPENSES!F:F, Data_Consolidado!A8, EXPENSES!E:E, "Shared") -> 10324 | H8: =G8*F8 -> 6013.4457 | I8: =E8+H8 -> 17043.446 | J8: =C8-I8 -> 51519.154 | K8: =IF(C8=0, "-", (J8/C8)) -> 0.75141775 | L8: =SUMIFS(Reference_Nights[[#All],[Available_nights]], Reference_Nights[[#All],[Month]], Table2[[#This Row],[Month]], Reference_Nights[[#All],[Apt]], Table2[[#This Row],[Apt]]) -> 27 | M8: =IF(Table2[[#This Row],[Available _Nights]]=0, 0, Table2[[#This Row],[Booked_Nights]]/Table2[[#This Row],[Available _Nights]]) -> 0.96296296 | N8: =IF(Table2[[#This Row],[Booked_Nights]]=0, 0, Table2[[#This Row],[Income]]/Table2[[#This Row],[Booked_Nights]]) -> 2637.0231 | O8: =IF(L8=0,0, Table2[[#This Row],[Income]]/Table2[[#This Row],[Available _Nights]]) -> 2539.3556 | P8: =IF(Table2[[#This Row],[Income]]=0,0,Table2[[#This Row],[Total_Exp]]/Table2[[#This Row],[Income]]) -> 0.24858225
A9: 2022-04 | B9: B303 | C9: =SUMIFS(Table1[FULL AMOUNT mxn pesos], Table1[Month], A9, Table1[APARTMENT], B9) -> 49147 | D9: =SUMIFS(INCOME!C:C, INCOME!D:D, Table2[[#This Row],[Apt]], INCOME!J:J, Table2[[#This Row],[Month]]) -> 21 | E9: =SUMIFS(EXPENSES!$D:$D, EXPENSES!$C:$C, B9, EXPENSES!$F:$F, A9, EXPENSES!$E:$E, "Direct") -> 6170 | F9: =IF(C9=0,0,C9/SUMIF(A:A,A9,C:C)) -> 0.41752754 | G9: =SUMIFS(EXPENSES!D:D, EXPENSES!F:F, Data_Consolidado!A9, EXPENSES!E:E, "Shared") -> 10324 | H9: =G9*F9 -> 4310.5543 | I9: =E9+H9 -> 10480.554 | J9: =C9-I9 -> 38666.446 | K9: =IF(C9=0, "-", (J9/C9)) -> 0.78675088 | L9: =SUMIFS(Reference_Nights[[#All],[Available_nights]], Reference_Nights[[#All],[Month]], Table2[[#This Row],[Month]], Reference_Nights[[#All],[Apt]], Table2[[#This Row],[Apt]]) -> 27 | M9: =IF(Table2[[#This Row],[Available _Nights]]=0, 0, Table2[[#This Row],[Booked_Nights]]/Table2[[#This Row],[Available _Nights]]) -> 0.77777778 | N9: =IF(Table2[[#This Row],[Booked_Nights]]=0, 0, Table2[[#This Row],[Income]]/Table2[[#This Row],[Booked_Nights]]) -> 2340.3333 | O9: =IF(L9=0,0, Table2[[#This Row],[Income]]/Table2[[#This Row],[Available _Nights]]) -> 1820.2593 | P9: =IF(Table2[[#This Row],[Income]]=0,0,Table2[[#This Row],[Total_Exp]]/Table2[[#This Row],[Income]]) -> 0.21324912
A10: 2022-05 | B10: A302 | C10: =SUMIFS(Table1[FULL AMOUNT mxn pesos], Table1[Month], A10, Table1[APARTMENT], B10) -> 71984.2 | D10: =SUMIFS(INCOME!C:C, INCOME!D:D, Table2[[#This Row],[Apt]], INCOME!J:J, Table2[[#This Row],[Month]]) -> 35 | E10: =SUMIFS(EXPENSES!$D:$D, EXPENSES!$C:$C, B10, EXPENSES!$F:$F, A10, EXPENSES!$E:$E, "Direct") -> 6916 | F10: =IF(C10=0,0,C10/SUMIF(A:A,A10,C:C)) -> 0.55374677 | G10: =SUMIFS(EXPENSES!D:D, EXPENSES!F:F, Data_Consolidado!A10, EXPENSES!E:E, "Shared") -> 8041 | H10: =G10*F10 -> 4452.6777 | I10: =E10+H10 -> 11368.678 | J10: =C10-I10 -> 60615.522 | K10: =IF(C10=0, "-", (J10/C10)) -> 0.84206704 | L10: =SUMIFS(Reference_Nights[[#All],[Available_nights]], Reference_Nights[[#All],[Month]], Table2[[#This Row],[Month]], Reference_Nights[[#All],[Apt]], Table2[[#This Row],[Apt]]) -> 28 | M10: =IF(Table2[[#This Row],[Available _Nights]]=0, 0, Table2[[#This Row],[Booked_Nights]]/Table2[[#This Row],[Available _Nights]]) -> 1.25 | N10: =IF(Table2[[#This Row],[Booked_Nights]]=0, 0, Table2[[#This Row],[Income]]/Table2[[#This Row],[Booked_Nights]]) -> 2056.6914 | O10: =IF(L10=0,0, Table2[[#This Row],[Income]]/Table2[[#This Row],[Available _Nights]]) -> 2570.8643 | P10: =IF(Table2[[#This Row],[Income]]=0,0,Table2[[#This Row],[Total_Exp]]/Table2[[#This Row],[Income]]) -> 0.15793296
A11: 2022-05 | B11: B303 | C11: =SUMIFS(Table1[FULL AMOUNT mxn pesos], Table1[Month], A11, Table1[APARTMENT], B11) -> 58010.6 | D11: =SUMIFS(INCOME!C:C, INCOME!D:D, Table2[[#This Row],[Apt]], INCOME!J:J, Table2[[#This Row],[Month]]) -> 28 | E11: =SUMIFS(EXPENSES!$D:$D, EXPENSES!$C:$C, B11, EXPENSES!$F:$F, A11, EXPENSES!$E:$E, "Direct") -> 6591 | F11: =IF(C11=0,0,C11/SUMIF(A:A,A11,C:C)) -> 0.44625323 | G11: =SUMIFS(EXPENSES!D:D, EXPENSES!F:F, Data_Consolidado!A11, EXPENSES!E:E, "Shared") -> 8041 | H11: =G11*F11 -> 3588.3223 | I11: =E11+H11 -> 10179.322 | J11: =C11-I11 -> 47831.278 | K11: =IF(C11=0, "-", (J11/C11)) -> 0.82452651 | L11: =SUMIFS(Reference_Nights[[#All],[Available_nights]], Reference_Nights[[#All],[Month]], Table2[[#This Row],[Month]], Reference_Nights[[#All],[Apt]], Table2[[#This Row],[Apt]]) -> 28 | M11: =IF(Table2[[#This Row],[Available _Nights]]=0, 0, Table2[[#This Row],[Booked_Nights]]/Table2[[#This Row],[Available _Nights]]) -> 1 | N11: =IF(Table2[[#This Row],[Booked_Nights]]=0, 0, Table2[[#This Row],[Income]]/Table2[[#This Row],[Booked_Nights]]) -> 2071.8071 | O11: =IF(L11=0,0, Table2[[#This Row],[Income]]/Table2[[#This Row],[Available _Nights]]) -> 2071.8071 | P11: =IF(Table2[[#This Row],[Income]]=0,0,Table2[[#This Row],[Total_Exp]]/Table2[[#This Row],[Income]]) -> 0.17547349
A12: 2022-06 | B12: A302 | C12: =SUMIFS(Table1[FULL AMOUNT mxn pesos], Table1[Month], A12, Table1[APARTMENT], B12) -> 9130.4 | D12: =SUMIFS(INCOME!C:C, INCOME!D:D, Table2[[#This Row],[Apt]], INCOME!J:J, Table2[[#This Row],[Month]]) -> 6 | E12: =SUMIFS(EXPENSES!$D:$D, EXPENSES!$C:$C, B12, EXPENSES!$F:$F, A12, EXPENSES!$E:$E, "Direct") -> 4015 | F12: =IF(C12=0,0,C12/SUMIF(A:A,A12,C:C)) -> 0.2534434 | G12: =SUMIFS(EXPENSES!D:D, EXPENSES!F:F, Data_Consolidado!A12, EXPENSES!E:E, "Shared") -> 7602 | H12: =G12*F12 -> 1926.6768 | I12: =E12+H12 -> 5941.6768 | J12: =C12-I12 -> 3188.7232 | K12: =IF(C12=0, "-", (J12/C12)) -> 0.34924245 | L12: =SUMIFS(Reference_Nights[[#All],[Available_nights]], Reference_Nights[[#All],[Month]], Table2[[#This Row],[Month]], Reference_Nights[[#All],[Apt]], Table2[[#This Row],[Apt]]) -> 27 | M12: =IF(Table2[[#This Row],[Available _Nights]]=0, 0, Table2[[#This Row],[Booked_Nights]]/Table2[[#This Row],[Available _Nights]]) -> 0.22222222 | N12: =IF(Table2[[#This Row],[Booked_Nights]]=0, 0, Table2[[#This Row],[Income]]/Table2[[#This Row],[Booked_Nights]]) -> 1521.7333 | O12: =IF(L12=0,0, Table2[[#This Row],[Income]]/Table2[[#This Row],[Available _Nights]]) -> 338.16296 | P12: =IF(Table2[[#This Row],[Income]]=0,0,Table2[[#This Row],[Total_Exp]]/Table2[[#This Row],[Income]]) -> 0.65075755
A13: 2022-06 | B13: B303 | C13: =SUMIFS(Table1[FULL AMOUNT mxn pesos], Table1[Month], A13, Table1[APARTMENT], B13) -> 26895 | D13: =SUMIFS(INCOME!C:C, INCOME!D:D, Table2[[#This Row],[Apt]], INCOME!J:J, Table2[[#This Row],[Month]]) -> 15 | E13: =SUMIFS(EXPENSES!$D:$D, EXPENSES!$C:$C, B13, EXPENSES!$F:$F, A13, EXPENSES!$E:$E, "Direct") -> 8211 | F13: =IF(C13=0,0,C13/SUMIF(A:A,A13,C:C)) -> 0.7465566 | G13: =SUMIFS(EXPENSES!D:D, EXPENSES!F:F, Data_Consolidado!A13, EXPENSES!E:E, "Shared") -> 7602 | H13: =G13*F13 -> 5675.3232 | I13: =E13+H13 -> 13886.323 | J13: =C13-I13 -> 13008.677 | K13: =IF(C13=0, "-", (J13/C13)) -> 0.48368384 | L13: =SUMIFS(Reference_Nights[[#All],[Available_nights]], Reference_Nights[[#All],[Month]], Table2[[#This Row],[Month]], Reference_Nights[[#All],[Apt]], Table2[[#This Row],[Apt]]) -> 27 | M13: =IF(Table2[[#This Row],[Available _Nights]]=0, 0, Table2[[#This Row],[Booked_Nights]]/Table2[[#This Row],[Available _Nights]]) -> 0.55555556 | N13: =IF(Table2[[#This Row],[Booked_Nights]]=0, 0, Table2[[#This Row],[Income]]/Table2[[#This Row],[Booked_Nights]]) -> 1793 | O13: =IF(L13=0,0, Table2[[#This Row],[Income]]/Table2[[#This Row],[Available _Nights]]) -> 996.11111 | P13: =IF(Table2[[#This Row],[Income]]=0,0,Table2[[#This Row],[Total_Exp]]/Table2[[#This Row],[Income]]) -> 0.51631616
A14: 2022-06 | B14: C301 | C14: =SUMIFS(Table1[FULL AMOUNT mxn pesos], Table1[Month], A14, Table1[APARTMENT], B14) -> 0 | D14: =SUMIFS(INCOME!C:C, INCOME!D:D, Table2[[#This Row],[Apt]], INCOME!J:J, Table2[[#This Row],[Month]]) -> 0 | E14: =SUMIFS(EXPENSES!$D:$D, EXPENSES!$C:$C, B14, EXPENSES!$F:$F, A14, EXPENSES!$E:$E, "Direct") -> 2600 | F14: =IF(C14=0,0,C14/SUMIF(A:A,A14,C:C)) -> 0 | G14: =SUMIFS(EXPENSES!D:D, EXPENSES!F:F, Data_Consolidado!A14, EXPENSES!E:E, "Shared") -> 7602 | H14: =G14*F14 -> 0 | I14: =E14+H14 -> 2600 | J14: =C14-I14 -> -2600 | K14: =IF(C14=0, "-", (J14/C14)) -> - | L14: =SUMIFS(Reference_Nights[[#All],[Available_nights]], Reference_Nights[[#All],[Month]], Table2[[#This Row],[Month]], Reference_Nights[[#All],[Apt]], Table2[[#This Row],[Apt]]) -> 27 | M14: =IF(Table2[[#This Row],[Available _Nights]]=0, 0, Table2[[#This Row],[Booked_Nights]]/Table2[[#This Row],[Available _Nights]]) -> 0 | N14: =IF(Table2[[#This Row],[Booked_Nights]]=0, 0, Table2[[#This Row],[Income]]/Table2[[#This Row],[Booked_Nights]]) -> 0 | O14: =IF(L14=0,0, Table2[[#This Row],[Income]]/Table2[[#This Row],[Available _Nights]]) -> 0 | P14: =IF(Table2[[#This Row],[Income]]=0,0,Table2[[#This Row],[Total_Exp]]/Table2[[#This Row],[Income]]) -> 0
A15: 2022-07 | B15: A302 | C15: =SUMIFS(Table1[FULL AMOUNT mxn pesos], Table1[Month], A15, Table1[APARTMENT], B15) -> 43007.8 | D15: =SUMIFS(INCOME!C:C, INCOME!D:D, Table2[[#This Row],[Apt]], INCOME!J:J, Table2[[#This Row],[Month]]) -> 13 | E15: =SUMIFS(EXPENSES!$D:$D, EXPENSES!$C:$C, B15, EXPENSES!$F:$F, A15, EXPENSES!$E:$E, "Direct") -> 13166 | F15: =IF(C15=0,0,C15/SUMIF(A:A,A15,C:C)) -> 0.48660055 | G15: =SUMIFS(EXPENSES!D:D, EXPENSES!F:F, Data_Consolidado!A15, EXPENSES!E:E, "Shared") -> 10489 | H15: =G15*F15 -> 5103.9531 | I15: =E15+H15 -> 18269.953 | J15: =C15-I15 -> 24737.847 | K15: =IF(C15=0, "-", (J15/C15)) -> 0.57519443 | L15: =SUMIFS(Reference_Nights[[#All],[Available_nights]], Reference_Nights[[#All],[Month]], Table2[[#This Row],[Month]], Reference_Nights[[#All],[Apt]], Table2[[#This Row],[Apt]]) -> 28 | M15: =IF(Table2[[#This Row],[Available _Nights]]=0, 0, Table2[[#This Row],[Booked_Nights]]/Table2[[#This Row],[Available _Nights]]) -> 0.46428571 | N15: =IF(Table2[[#This Row],[Booked_Nights]]=0, 0, Table2[[#This Row],[Income]]/Table2[[#This Row],[Booked_Nights]]) -> 3308.2923 | O15: =IF(L15=0,0, Table2[[#This Row],[Income]]/Table2[[#This Row],[Available _Nights]]) -> 1535.9929 | P15: =IF(Table2[[#This Row],[Income]]=0,0,Table2[[#This Row],[Total_Exp]]/Table2[[#This Row],[Income]]) -> 0.42480557
A16: 2022-07 | B16: B303 | C16: =SUMIFS(Table1[FULL AMOUNT mxn pesos], Table1[Month], A16, Table1[APARTMENT], B16) -> 45376.4 | D16: =SUMIFS(INCOME!C:C, INCOME!D:D, Table2[[#This Row],[Apt]], INCOME!J:J, Table2[[#This Row],[Month]]) -> 22 | E16: =SUMIFS(EXPENSES!$D:$D, EXPENSES!$C:$C, B16, EXPENSES!$F:$F, A16, EXPENSES!$E:$E, "Direct") -> 14801 | F16: =IF(C16=0,0,C16/SUMIF(A:A,A16,C:C)) -> 0.51339945 | G16: =SUMIFS(EXPENSES!D:D, EXPENSES!F:F, Data_Consolidado!A16, EXPENSES!E:E, "Shared") -> 10489 | H16: =G16*F16 -> 5385.0469 | I16: =E16+H16 -> 20186.047 | J16: =C16-I16 -> 25190.353 | K16: =IF(C16=0, "-", (J16/C16)) -> 0.55514217 | L16: =SUMIFS(Reference_Nights[[#All],[Available_nights]], Reference_Nights[[#All],[Month]], Table2[[#This Row],[Month]], Reference_Nights[[#All],[Apt]], Table2[[#This Row],[Apt]]) -> 28 | M16: =IF(Table2[[#This Row],[Available _Nights]]=0, 0, Table2[[#This Row],[Booked_Nights]]/Table2[[#This Row],[Available _Nights]]) -> 0.78571429 | N16: =IF(Table2[[#This Row],[Booked_Nights]]=0, 0, Table2[[#This Row],[Income]]/Table2[[#This Row],[Booked_Nights]]) -> 2062.5636 | O16: =IF(L16=0,0, Table2[[#This Row],[Income]]/Table2[[#This Row],[Available _Nights]]) -> 1620.5857 | P16: =IF(Table2[[#This Row],[Income]]=0,0,Table2[[#This Row],[Total_Exp]]/Table2[[#This Row],[Income]]) -> 0.44485783
A17: 2022-07 | B17: C301 | C17: =SUMIFS(Table1[FULL AMOUNT mxn pesos], Table1[Month], A17, Table1[APARTMENT], B17) -> 0 | D17: =SUMIFS(INCOME!C:C, INCOME!D:D, Table2[[#This Row],[Apt]], INCOME!J:J, Table2[[#This Row],[Month]]) -> 0 | E17: =SUMIFS(EXPENSES!$D:$D, EXPENSES!$C:$C, B17, EXPENSES!$F:$F, A17, EXPENSES!$E:$E, "Direct") -> 10533 | F17: =IF(C17=0,0,C17/SUMIF(A:A,A17,C:C)) -> 0 | G17: =SUMIFS(EXPENSES!D:D, EXPENSES!F:F, Data_Consolidado!A17, EXPENSES!E:E, "Shared") -> 10489 | H17: =G17*F17 -> 0 | I17: =E17+H17 -> 10533 | J17: =C17-I17 -> -10533 | K17: =IF(C17=0, "-", (J17/C17)) -> - | L17: =SUMIFS(Reference_Nights[[#All],[Available_nights]], Reference_Nights[[#All],[Month]], Table2[[#This Row],[Month]], Reference_Nights[[#All],[Apt]], Table2[[#This Row],[Apt]]) -> 28 | M17: =IF(Table2[[#This Row],[Available _Nights]]=0, 0, Table2[[#This Row],[Booked_Nights]]/Table2[[#This Row],[Available _Nights]]) -> 0 | N17: =IF(Table2[[#This Row],[Booked_Nights]]=0, 0, Table2[[#This Row],[Income]]/Table2[[#This Row],[Booked_Nights]]) -> 0 | O17: =IF(L17=0,0, Table2[[#This Row],[Income]]/Table2[[#This Row],[Available _Nights]]) -> 0 | P17: =IF(Table2[[#This Row],[Income]]=0,0,Table2[[#This Row],[Total_Exp]]/Table2[[#This Row],[Income]]) -> 0
... A20: 2022-08 | B20: C301 | C20: =SUMIFS(Table1[FULL AMOUNT mxn pesos], Table1[Month], A20, Table1[APARTMENT], B20) -> 19489.2 | D20: =SUMIFS(INCOME!C:C, INCOME!D:D, Table2[[#This Row],[Apt]], INCOME!J:J, Table2[[#This Row],[Month]]) -> 17 | E20: =SUMIFS(EXPENSES!$D:$D, EXPENSES!$C:$C, B20, EXPENSES!$F:$F, A20, EXPENSES!$E:$E, "Direct") -> 49302 | F20: =IF(C20=0,0,C20/SUMIF(A:A,A20,C:C)) -> 0.33803843 | G20: =SUMIFS(EXPENSES!D:D, EXPENSES!F:F, Data_Consolidado!A20, EXPENSES!E:E, "Shared") -> 14507 | H20: =G20*F20 -> 4903.9235 | I20: =E20+H20 -> 54205.923 | J20: =C20-I20 -> -34716.723 | K20: =IF(C20=0, "-", (J20/C20)) -> -1.7813314 | L20: =SUMIFS(Reference_Nights[[#All],[Available_nights]], Reference_Nights[[#All],[Month]], Table2[[#This Row],[Month]], Reference_Nights[[#All],[Apt]], Table2[[#This Row],[Apt]]) -> 28 | M20: =IF(Table2[[#This Row],[Available _Nights]]=0, 0, Table2[[#This Row],[Booked_Nights]]/Table2[[#This Row],[Available _Nights]]) -> 0.60714286 | N20: =IF(Table2[[#This Row],[Booked_Nights]]=0, 0, Table2[[#This Row],[Income]]/Table2[[#This Row],[Booked_Nights]]) -> 1146.4235 | O20: =IF(L20=0,0, Table2[[#This Row],[Income]]/Table2[[#This Row],[Available _Nights]]) -> 696.04286 | P20: =IF(Table2[[#This Row],[Income]]=0,0,Table2[[#This Row],[Total_Exp]]/Table2[[#This Row],[Income]]) -> 2.7813314
A21: 2022-09 | B21: A302 | C21: =SUMIFS(Table1[FULL AMOUNT mxn pesos], Table1[Month], A21, Table1[APARTMENT], B21) -> 0 | D21: =SUMIFS(INCOME!C:C, INCOME!D:D, Table2[[#This Row],[Apt]], INCOME!J:J, Table2[[#This Row],[Month]]) -> 0 | E21: =SUMIFS(EXPENSES!$D:$D, EXPENSES!$C:$C, B21, EXPENSES!$F:$F, A21, EXPENSES!$E:$E, "Direct") -> 3550 | F21: =IF(C21=0,0,C21/SUMIF(A:A,A21,C:C)) -> 0 | G21: =SUMIFS(EXPENSES!D:D, EXPENSES!F:F, Data_Consolidado!A21, EXPENSES!E:E, "Shared") -> 7560.2 | H21: =Table2[[#This Row],[Shared_Total]]/3 -> 2520.0667 | I21: =E21+H21 -> 6070.0667 | J21: =C21-I21 -> -6070.0667 | K21: =IF(C21=0, "-", (J21/C21)) -> - | L21: =SUMIFS(Reference_Nights[[#All],[Available_nights]], Reference_Nights[[#All],[Month]], Table2[[#This Row],[Month]], Reference_Nights[[#All],[Apt]], Table2[[#This Row],[Apt]]) -> 27 | M21: =IF(Table2[[#This Row],[Available _Nights]]=0, 0, Table2[[#This Row],[Booked_Nights]]/Table2[[#This Row],[Available _Nights]]) -> 0 | N21: =IF(Table2[[#This Row],[Booked_Nights]]=0, 0, Table2[[#This Row],[Income]]/Table2[[#This Row],[Booked_Nights]]) -> 0 | O21: =IF(L21=0,0, Table2[[#This Row],[Income]]/Table2[[#This Row],[Available _Nights]]) -> 0 | P21: =IF(Table2[[#This Row],[Income]]=0,0,Table2[[#This Row],[Total_Exp]]/Table2[[#This Row],[Income]]) -> 0
A22: 2022-09 | B22: B303 | C22: =SUMIFS(Table1[FULL AMOUNT mxn pesos], Table1[Month], A22, Table1[APARTMENT], B22) -> 0 | D22: =SUMIFS(INCOME!C:C, INCOME!D:D, Table2[[#This Row],[Apt]], INCOME!J:J, Table2[[#This Row],[Month]]) -> 0 | E22: =SUMIFS(EXPENSES!$D:$D, EXPENSES!$C:$C, B22, EXPENSES!$F:$F, A22, EXPENSES!$E:$E, "Direct") -> 0 | F22: =IF(C22=0,0,C22/SUMIF(A:A,A22,C:C)) -> 0 | G22: =SUMIFS(EXPENSES!D:D, EXPENSES!F:F, Data_Consolidado!A22, EXPENSES!E:E, "Shared") -> 7560.2 | H22: =Table2[[#This Row],[Shared_Total]]/3 -> 2520.0667 | I22: =E22+H22 -> 2520.0667 | J22: =C22-I22 -> -2520.0667 | K22: =IF(C22=0, "-", (J22/C22)) -> - | L22: =SUMIFS(Reference_Nights[[#All],[Available_nights]], Reference_Nights[[#All],[Month]], Table2[[#This Row],[Month]], Reference_Nights[[#All],[Apt]], Table2[[#This Row],[Apt]]) -> 27 | M22: =IF(Table2[[#This Row],[Available _Nights]]=0, 0, Table2[[#This Row],[Booked_Nights]]/Table2[[#This Row],[Available _Nights]]) -> 0 | N22: =IF(Table2[[#This Row],[Booked_Nights]]=0, 0, Table2[[#This Row],[Income]]/Table2[[#This Row],[Booked_Nights]]) -> 0 | O22: =IF(L22=0,0, Table2[[#This Row],[Income]]/Table2[[#This Row],[Available _Nights]]) -> 0 | P22: =IF(Table2[[#This Row],[Income]]=0,0,Table2[[#This Row],[Total_Exp]]/Table2[[#This Row],[Income]]) -> 0
A23: 2022-09 | B23: C301 | C23: =SUMIFS(Table1[FULL AMOUNT mxn pesos], Table1[Month], A23, Table1[APARTMENT], B23) -> 0 | D23: =SUMIFS(INCOME!C:C, INCOME!D:D, Table2[[#This Row],[Apt]], INCOME!J:J, Table2[[#This Row],[Month]]) -> 0 | E23: =SUMIFS(EXPENSES!$D:$D, EXPENSES!$C:$C, B23, EXPENSES!$F:$F, A23, EXPENSES!$E:$E, "Direct") -> 1900 | F23: =IF(C23=0,0,C23/SUMIF(A:A,A23,C:C)) -> 0 | G23: =SUMIFS(EXPENSES!D:D, EXPENSES!F:F, Data_Consolidado!A23, EXPENSES!E:E, "Shared") -> 7560.2 | H23: =Table2[[#This Row],[Shared_Total]]/3 -> 2520.0667 | I23: =E23+H23 -> 4420.0667 | J23: =C23-I23 -> -4420.0667 | K23: =IF(C23=0, "-", (J23/C23)) -> - | L23: =SUMIFS(Reference_Nights[[#All],[Available_nights]], Reference_Nights[[#All],[Month]], Table2[[#This Row],[Month]], Reference_Nights[[#All],[Apt]], Table2[[#This Row],[Apt]]) -> 27 | M23: =IF(Table2[[#This Row],[Available _Nights]]=0, 0, Table2[[#This Row],[Booked_Nights]]/Table2[[#This Row],[Available _Nights]]) -> 0 | N23: =IF(Table2[[#This Row],[Booked_Nights]]=0, 0, Table2[[#This Row],[Income]]/Table2[[#This Row],[Booked_Nights]]) -> 0 | O23: =IF(L23=0,0, Table2[[#This Row],[Income]]/Table2[[#This Row],[Available _Nights]]) -> 0 | P23: =IF(Table2[[#This Row],[Income]]=0,0,Table2[[#This Row],[Total_Exp]]/Table2[[#This Row],[Income]]) -> 0
A24: 2022-10 | B24: A302 | C24: =SUMIFS(Table1[FULL AMOUNT mxn pesos], Table1[Month], A24, Table1[APARTMENT], B24) -> 18000 | D24: =SUMIFS(INCOME!C:C, INCOME!D:D, Table2[[#This Row],[Apt]], INCOME!J:J, Table2[[#This Row],[Month]]) -> 10 | E24: =SUMIFS(EXPENSES!$D:$D, EXPENSES!$C:$C, B24, EXPENSES!$F:$F, A24, EXPENSES!$E:$E, "Direct") -> 6267 | F24: =IF(C24=0,0,C24/SUMIF(A:A,A24,C:C)) -> 1 | G24: =SUMIFS(EXPENSES!D:D, EXPENSES!F:F, Data_Consolidado!A24, EXPENSES!E:E, "Shared") -> 15960 | H24: =G24*F24 -> 15960 | I24: =E24+H24 -> 22227 | J24: =C24-I24 -> -4227 | K24: =IF(C24=0, "-", (J24/C24)) -> -0.23483333 | L24: =SUMIFS(Reference_Nights[[#All],[Available_nights]], Reference_Nights[[#All],[Month]], Table2[[#This Row],[Month]], Reference_Nights[[#All],[Apt]], Table2[[#This Row],[Apt]]) -> 28 | M24: =IF(Table2[[#This Row],[Available _Nights]]=0, 0, Table2[[#This Row],[Booked_Nights]]/Table2[[#This Row],[Available _Nights]]) -> 0.35714286 | N24: =IF(Table2[[#This Row],[Booked_Nights]]=0, 0, Table2[[#This Row],[Income]]/Table2[[#This Row],[Booked_Nights]]) -> 1800 | O24: =IF(L24=0,0, Table2[[#This Row],[Income]]/Table2[[#This Row],[Available _Nights]]) -> 642.85714 | P24: =IF(Table2[[#This Row],[Income]]=0,0,Table2[[#This Row],[Total_Exp]]/Table2[[#This Row],[Income]]) -> 1.2348333
A25: 2022-10 | B25: B303 | C25: =SUMIFS(Table1[FULL AMOUNT mxn pesos], Table1[Month], A25, Table1[APARTMENT], B25) -> 0 | D25: =SUMIFS(INCOME!C:C, INCOME!D:D, Table2[[#This Row],[Apt]], INCOME!J:J, Table2[[#This Row],[Month]]) -> 0 | E25: =SUMIFS(EXPENSES!$D:$D, EXPENSES!$C:$C, B25, EXPENSES!$F:$F, A25, EXPENSES!$E:$E, "Direct") -> 700 | F25: =IF(C25=0,0,C25/SUMIF(A:A,A25,C:C)) -> 0 | G25: =SUMIFS(EXPENSES!D:D, EXPENSES!F:F, Data_Consolidado!A25, EXPENSES!E:E, "Shared") -> 15960 | H25: =G25*F25 -> 0 | I25: =E25+H25 -> 700 | J25: =C25-I25 -> -700 | K25: =IF(C25=0, "-", (J25/C25)) -> - | L25: =SUMIFS(Reference_Nights[[#All],[Available_nights]], Reference_Nights[[#All],[Month]], Table2[[#This Row],[Month]], Reference_Nights[[#All],[Apt]], Table2[[#This Row],[Apt]]) -> 28 | M25: =IF(Table2[[#This Row],[Available _Nights]]=0, 0, Table2[[#This Row],[Booked_Nights]]/Table2[[#This Row],[Available _Nights]]) -> 0 | N25: =IF(Table2[[#This Row],[Booked_Nights]]=0, 0, Table2[[#This Row],[Income]]/Table2[[#This Row],[Booked_Nights]]) -> 0 | O25: =IF(L25=0,0, Table2[[#This Row],[Income]]/Table2[[#This Row],[Available _Nights]]) -> 0 | P25: =IF(Table2[[#This Row],[Income]]=0,0,Table2[[#This Row],[Total_Exp]]/Table2[[#This Row],[Income]]) -> 0
A26: 2022-10 | B26: C301 | C26: =SUMIFS(Table1[FULL AMOUNT mxn pesos], Table1[Month], A26, Table1[APARTMENT], B26) -> 0 | D26: =SUMIFS(INCOME!C:C, INCOME!D:D, Table2[[#This Row],[Apt]], INCOME!J:J, Table2[[#This Row],[Month]]) -> 0 | E26: =SUMIFS(EXPENSES!$D:$D, EXPENSES!$C:$C, B26, EXPENSES!$F:$F, A26, EXPENSES!$E:$E, "Direct") -> 4200 | F26: =IF(C26=0,0,C26/SUMIF(A:A,A26,C:C)) -> 0 | G26: =SUMIFS(EXPENSES!D:D, EXPENSES!F:F, Data_Consolidado!A26, EXPENSES!E:E, "Shared") -> 15960 | H26: =G26*F26 -> 0 | I26: =E26+H26 -> 4200 | J26: =C26-I26 -> -4200 | K26: =IF(C26=0, "-", (J26/C26)) -> - | L26: =SUMIFS(Reference_Nights[[#All],[Available_nights]], Reference_Nights[[#All],[Month]], Table2[[#This Row],[Month]], Reference_Nights[[#All],[Apt]], Table2[[#This Row],[Apt]]) -> 28 | M26: =IF(Table2[[#This Row],[Available _Nights]]=0, 0, Table2[[#This Row],[Booked_Nights]]/Table2[[#This Row],[Available _Nights]]) -> 0 | N26: =IF(Table2[[#This Row],[Booked_Nights]]=0, 0, Table2[[#This Row],[Income]]/Table2[[#This Row],[Booked_Nights]]) -> 0 | O26: =IF(L26=0,0, Table2[[#This Row],[Income]]/Table2[[#This Row],[Available _Nights]]) -> 0 | P26: =IF(Table2[[#This Row],[Income]]=0,0,Table2[[#This Row],[Total_Exp]]/Table2[[#This Row],[Income]]) -> 0
A27: 2022-11 | B27: A302 | C27: =SUMIFS(Table1[FULL AMOUNT mxn pesos], Table1[Month], A27, Table1[APARTMENT], B27) -> 49329.6 | D27: =SUMIFS(INCOME!C:C, INCOME!D:D, Table2[[#This Row],[Apt]], INCOME!J:J, Table2[[#This Row],[Month]]) -> 26 | E27: =SUMIFS(EXPENSES!$D:$D, EXPENSES!$C:$C, B27, EXPENSES!$F:$F, A27, EXPENSES!$E:$E, "Direct") -> 11600 | F27: =IF(C27=0,0,C27/SUMIF(A:A,A27,C:C)) -> 0.67306307 | G27: =SUMIFS(EXPENSES!D:D, EXPENSES!F:F, Data_Consolidado!A27, EXPENSES!E:E, "Shared") -> 38209 | H27: =G27*F27 -> 25717.067 | I27: =E27+H27 -> 37317.067 | J27: =C27-I27 -> 12012.533 | K27: =IF(C27=0, "-", (J27/C27)) -> 0.24351572 | L27: =SUMIFS(Reference_Nights[[#All],[Available_nights]], Reference_Nights[[#All],[Month]], Table2[[#This Row],[Month]], Reference_Nights[[#All],[Apt]], Table2[[#This Row],[Apt]]) -> 27 | M27: =IF(Table2[[#This Row],[Available _Nights]]=0, 0, Table2[[#This Row],[Booked_Nights]]/Table2[[#This Row],[Available _Nights]]) -> 0.96296296 | N27: =IF(Table2[[#This Row],[Booked_Nights]]=0, 0, Table2[[#This Row],[Income]]/Table2[[#This Row],[Booked_Nights]]) -> 1897.2923 | O27: =IF(L27=0,0, Table2[[#This Row],[Income]]/Table2[[#This Row],[Available _Nights]]) -> 1827.0222 | P27: =IF(Table2[[#This Row],[Income]]=0,0,Table2[[#This Row],[Total_Exp]]/Table2[[#This Row],[Income]]) -> 0.75648428
A28: 2022-11 | B28: B303 | C28: =SUMIFS(Table1[FULL AMOUNT mxn pesos], Table1[Month], A28, Table1[APARTMENT], B28) -> 12300 | D28: =SUMIFS(INCOME!C:C, INCOME!D:D, Table2[[#This Row],[Apt]], INCOME!J:J, Table2[[#This Row],[Month]]) -> 6 | E28: =SUMIFS(EXPENSES!$D:$D, EXPENSES!$C:$C, B28, EXPENSES!$F:$F, A28, EXPENSES!$E:$E, "Direct") -> 4470 | F28: =IF(C28=0,0,C28/SUMIF(A:A,A28,C:C)) -> 0.1678237 | G28: =SUMIFS(EXPENSES!D:D, EXPENSES!F:F, Data_Consolidado!A28, EXPENSES!E:E, "Shared") -> 38209 | H28: =G28*F28 -> 6412.3756 | I28: =E28+H28 -> 10882.376 | J28: =C28-I28 -> 1417.6244 | K28: =IF(C28=0, "-", (J28/C28)) -> 0.11525402 | L28: =SUMIFS(Reference_Nights[[#All],[Available_nights]], Reference_Nights[[#All],[Month]], Table2[[#This Row],[Month]], Reference_Nights[[#All],[Apt]], Table2[[#This Row],[Apt]]) -> 27 | M28: =IF(Table2[[#This Row],[Available _Nights]]=0, 0, Table2[[#This Row],[Booked_Nights]]/Table2[[#This Row],[Available _Nights]]) -> 0.22222222 | N28: =IF(Table2[[#This Row],[Booked_Nights]]=0, 0, Table2[[#This Row],[Income]]/Table2[[#This Row],[Booked_Nights]]) -> 2050 | O28: =IF(L28=0,0, Table2[[#This Row],[Income]]/Table2[[#This Row],[Available _Nights]]) -> 455.55556 | P28: =IF(Table2[[#This Row],[Income]]=0,0,Table2[[#This Row],[Total_Exp]]/Table2[[#This Row],[Income]]) -> 0.88474598
A29: 2022-11 | B29: C301 | C29: =SUMIFS(Table1[FULL AMOUNT mxn pesos], Table1[Month], A29, Table1[APARTMENT], B29) -> 11661.6 | D29: =SUMIFS(INCOME!C:C, INCOME!D:D, Table2[[#This Row],[Apt]], INCOME!J:J, Table2[[#This Row],[Month]]) -> 8 | E29: =SUMIFS(EXPENSES!$D:$D, EXPENSES!$C:$C, B29, EXPENSES!$F:$F, A29, EXPENSES!$E:$E, "Direct") -> 23842 | F29: =IF(C29=0,0,C29/SUMIF(A:A,A29,C:C)) -> 0.15911324 | G29: =SUMIFS(EXPENSES!D:D, EXPENSES!F:F, Data_Consolidado!A29, EXPENSES!E:E, "Shared") -> 38209 | H29: =G29*F29 -> 6079.5576 | I29: =E29+H29 -> 29921.558 | J29: =C29-I29 -> -18259.958 | K29: =IF(C29=0, "-", (J29/C29)) -> -1.5658192 | L29: =SUMIFS(Reference_Nights[[#All],[Available_nights]], Reference_Nights[[#All],[Month]], Table2[[#This Row],[Month]], Reference_Nights[[#All],[Apt]], Table2[[#This Row],[Apt]]) -> 27 | M29: =IF(Table2[[#This Row],[Available _Nights]]=0, 0, Table2[[#This Row],[Booked_Nights]]/Table2[[#This Row],[Available _Nights]]) -> 0.2962963 | N29: =IF(Table2[[#This Row],[Booked_Nights]]=0, 0, Table2[[#This Row],[Income]]/Table2[[#This Row],[Booked_Nights]]) -> 1457.7 | O29: =IF(L29=0,0, Table2[[#This Row],[Income]]/Table2[[#This Row],[Available _Nights]]) -> 431.91111 | P29: =IF(Table2[[#This Row],[Income]]=0,0,Table2[[#This Row],[Total_Exp]]/Table2[[#This Row],[Income]]) -> 2.5658192
A30: 2022-12 | B30: A302 | C30: =SUMIFS(Table1[FULL AMOUNT mxn pesos], Table1[Month], A30, Table1[APARTMENT], B30) -> 56866.6 | D30: =SUMIFS(INCOME!C:C, INCOME!D:D, Table2[[#This Row],[Apt]], INCOME!J:J, Table2[[#This Row],[Month]]) -> 16 | E30: =SUMIFS(EXPENSES!$D:$D, EXPENSES!$C:$C, B30, EXPENSES!$F:$F, A30, EXPENSES!$E:$E, "Direct") -> 16310 | F30: =IF(C30=0,0,C30/SUMIF(A:A,A30,C:C)) -> 0.29099147 | G30: =SUMIFS(EXPENSES!D:D, EXPENSES!F:F, Data_Consolidado!A30, EXPENSES!E:E, "Shared") -> 22700 | H30: =G30*F30 -> 6605.5063 | I30: =E30+H30 -> 22915.506 | J30: =C30-I30 -> 33951.094 | K30: =IF(C30=0, "-", (J30/C30)) -> 0.59703048 | L30: =SUMIFS(Reference_Nights[[#All],[Available_nights]], Reference_Nights[[#All],[Month]], Table2[[#This Row],[Month]], Reference_Nights[[#All],[Apt]], Table2[[#This Row],[Apt]]) -> 28 | M30: =IF(Table2[[#This Row],[Available _Nights]]=0, 0, Table2[[#This Row],[Booked_Nights]]/Table2[[#This Row],[Available _Nights]]) -> 0.57142857 | N30: =IF(Table2[[#This Row],[Booked_Nights]]=0, 0, Table2[[#This Row],[Income]]/Table2[[#This Row],[Booked_Nights]]) -> 3554.1625 | O30: =IF(L30=0,0, Table2[[#This Row],[Income]]/Table2[[#This Row],[Available _Nights]]) -> 2030.95 | P30: =IF(Table2[[#This Row],[Income]]=0,0,Table2[[#This Row],[Total_Exp]]/Table2[[#This Row],[Income]]) -> 0.40296952
A31: 2022-12 | B31: B303 | C31: =SUMIFS(Table1[FULL AMOUNT mxn pesos], Table1[Month], A31, Table1[APARTMENT], B31) -> 74357 | D31: =SUMIFS(INCOME!C:C, INCOME!D:D, Table2[[#This Row],[Apt]], INCOME!J:J, Table2[[#This Row],[Month]]) -> 19 | E31: =SUMIFS(EXPENSES!$D:$D, EXPENSES!$C:$C, B31, EXPENSES!$F:$F, A31, EXPENSES!$E:$E, "Direct") -> 7460 | F31: =IF(C31=0,0,C31/SUMIF(A:A,A31,C:C)) -> 0.3804914 | G31: =SUMIFS(EXPENSES!D:D, EXPENSES!F:F, Data_Consolidado!A31, EXPENSES!E:E, "Shared") -> 22700 | H31: =G31*F31 -> 8637.1549 | I31: =E31+H31 -> 16097.155 | J31: =C31-I31 -> 58259.845 | K31: =IF(C31=0, "-", (J31/C31)) -> 0.78351527 | L31: =SUMIFS(Reference_Nights[[#All],[Available_nights]], Reference_Nights[[#All],[Month]], Table2[[#This Row],[Month]], Reference_Nights[[#All],[Apt]], Table2[[#This Row],[Apt]]) -> 28 | M31: =IF(Table2[[#This Row],[Available _Nights]]=0, 0, Table2[[#This Row],[Booked_Nights]]/Table2[[#This Row],[Available _Nights]]) -> 0.67857143 | N31: =IF(Table2[[#This Row],[Booked_Nights]]=0, 0, Table2[[#This Row],[Income]]/Table2[[#This Row],[Booked_Nights]]) -> 3913.5263 | O31: =IF(L31=0,0, Table2[[#This Row],[Income]]/Table2[[#This Row],[Available _Nights]]) -> 2655.6071 | P31: =IF(Table2[[#This Row],[Income]]=0,0,Table2[[#This Row],[Total_Exp]]/Table2[[#This Row],[Income]]) -> 0.21648473
A32: 2022-12 | B32: C301 | C32: =SUMIFS(Table1[FULL AMOUNT mxn pesos], Table1[Month], A32, Table1[APARTMENT], B32) -> 64200 | D32: =SUMIFS(INCOME!C:C, INCOME!D:D, Table2[[#This Row],[Apt]], INCOME!J:J, Table2[[#This Row],[Month]]) -> 42 | E32: =SUMIFS(EXPENSES!$D:$D, EXPENSES!$C:$C, B32, EXPENSES!$F:$F, A32, EXPENSES!$E:$E, "Direct") -> 7490 | F32: =IF(C32=0,0,C32/SUMIF(A:A,A32,C:C)) -> 0.32851713 | G32: =SUMIFS(EXPENSES!D:D, EXPENSES!F:F, Data_Consolidado!A32, EXPENSES!E:E, "Shared") -> 22700 | H32: =G32*F32 -> 7457.3388 | I32: =E32+H32 -> 14947.339 | J32: =C32-I32 -> 49252.661 | K32: =IF(C32=0, "-", (J32/C32)) -> 0.76717541 | L32: =SUMIFS(Reference_Nights[[#All],[Available_nights]], Reference_Nights[[#All],[Month]], Table2[[#This Row],[Month]], Reference_Nights[[#All],[Apt]], Table2[[#This Row],[Apt]]) -> 28 | M32: =IF(Table2[[#This Row],[Available _Nights]]=0, 0, Table2[[#This Row],[Booked_Nights]]/Table2[[#This Row],[Available _Nights]]) -> 1.5 | N32: =IF(Table2[[#This Row],[Booked_Nights]]=0, 0, Table2[[#This Row],[Income]]/Table2[[#This Row],[Booked_Nights]]) -> 1528.5714 | O32: =IF(L32=0,0, Table2[[#This Row],[Income]]/Table2[[#This Row],[Available _Nights]]) -> 2292.8571 | P32: =IF(Table2[[#This Row],[Income]]=0,0,Table2[[#This Row],[Total_Exp]]/Table2[[#This Row],[Income]]) -> 0.23282459
A33: 2023-01 | B33: A302 | C33: =SUMIFS(Table1[FULL AMOUNT mxn pesos], Table1[Month], A33, Table1[APARTMENT], B33) -> 127716.4 | D33: =SUMIFS(INCOME!C:C, INCOME!D:D, Table2[[#This Row],[Apt]], INCOME!J:J, Table2[[#This Row],[Month]]) -> 43 | E33: =SUMIFS(EXPENSES!$D:$D, EXPENSES!$C:$C, B33, EXPENSES!$F:$F, A33, EXPENSES!$E:$E, "Direct") -> 24790 | F33: =IF(C33=0,0,C33/SUMIF(A:A,A33,C:C)) -> 0.53977007 | G33: =SUMIFS(EXPENSES!D:D, EXPENSES!F:F, Data_Consolidado!A33, EXPENSES!E:E, "Shared") -> 11670 | H33: =G33*F33 -> 6299.1167 | I33: =E33+H33 -> 31089.117 | J33: =C33-I33 -> 96627.283 | K33: =IF(C33=0, "-", (J33/C33)) -> 0.75657694 | L33: =SUMIFS(Reference_Nights[[#All],[Available_nights]], Reference_Nights[[#All],[Month]], Table2[[#This Row],[Month]], Reference_Nights[[#All],[Apt]], Table2[[#This Row],[Apt]]) -> 28 | M33: =IF(Table2[[#This Row],[Available _Nights]]=0, 0, Table2[[#This Row],[Booked_Nights]]/Table2[[#This Row],[Available _Nights]]) -> 1.5357143 | N33: =IF(Table2[[#This Row],[Booked_Nights]]=0, 0, Table2[[#This Row],[Income]]/Table2[[#This Row],[Booked_Nights]]) -> 2970.1488 | O33: =IF(L33=0,0, Table2[[#This Row],[Income]]/Table2[[#This Row],[Available _Nights]]) -> 4561.3 | P33: =IF(Table2[[#This Row],[Income]]=0,0,Table2[[#This Row],[Total_Exp]]/Table2[[#This Row],[Income]]) -> 0.24342306
A34: 2023-01 | B34: B303 | C34: =SUMIFS(Table1[FULL AMOUNT mxn pesos], Table1[Month], A34, Table1[APARTMENT], B34) -> 36306.6 | D34: =SUMIFS(INCOME!C:C, INCOME!D:D, Table2[[#This Row],[Apt]], INCOME!J:J, Table2[[#This Row],[Month]]) -> 13 | E34: =SUMIFS(EXPENSES!$D:$D, EXPENSES!$C:$C, B34, EXPENSES!$F:$F, A34, EXPENSES!$E:$E, "Direct") -> 14670 | F34: =IF(C34=0,0,C34/SUMIF(A:A,A34,C:C)) -> 0.15344322 | G34: =SUMIFS(EXPENSES!D:D, EXPENSES!F:F, Data_Consolidado!A34, EXPENSES!E:E, "Shared") -> 11670 | H34: =G34*F34 -> 1790.6824 | I34: =E34+H34 -> 16460.682 | J34: =C34-I34 -> 19845.918 | K34: =IF(C34=0, "-", (J34/C34)) -> 0.54662011 | L34: =SUMIFS(Reference_Nights[[#All],[Available_nights]], Reference_Nights[[#All],[Month]], Table2[[#This Row],[Month]], Reference_Nights[[#All],[Apt]], Table2[[#This Row],[Apt]]) -> 28 | M34: =IF(Table2[[#This Row],[Available _Nights]]=0, 0, Table2[[#This Row],[Booked_Nights]]/Table2[[#This Row],[Available _Nights]]) -> 0.46428571 | N34: =IF(Table2[[#This Row],[Booked_Nights]]=0, 0, Table2[[#This Row],[Income]]/Table2[[#This Row],[Booked_Nights]]) -> 2792.8154 | O34: =IF(L34=0,0, Table2[[#This Row],[Income]]/Table2[[#This Row],[Available _Nights]]) -> 1296.6643 | P34: =IF(Table2[[#This Row],[Income]]=0,0,Table2[[#This Row],[Total_Exp]]/Table2[[#This Row],[Income]]) -> 0.45337989
A35: 2023-01 | B35: C301 | C35: =SUMIFS(Table1[FULL AMOUNT mxn pesos], Table1[Month], A35, Table1[APARTMENT], B35) -> 72589.6 | D35: =SUMIFS(INCOME!C:C, INCOME!D:D, Table2[[#This Row],[Apt]], INCOME!J:J, Table2[[#This Row],[Month]]) -> 22 | E35: =SUMIFS(EXPENSES!$D:$D, EXPENSES!$C:$C, B35, EXPENSES!$F:$F, A35, EXPENSES!$E:$E, "Direct") -> 17390 | F35: =IF(C35=0,0,C35/SUMIF(A:A,A35,C:C)) -> 0.30678671 | G35: =SUMIFS(EXPENSES!D:D, EXPENSES!F:F, Data_Consolidado!A35, EXPENSES!E:E, "Shared") -> 11670 | H35: =G35*F35 -> 3580.2009 | I35: =E35+H35 -> 20970.201 | J35: =C35-I35 -> 51619.399 | K35: =IF(C35=0, "-", (J35/C35)) -> 0.71111287 | L35: =SUMIFS(Reference_Nights[[#All],[Available_nights]], Reference_Nights[[#All],[Month]], Table2[[#This Row],[Month]], Reference_Nights[[#All],[Apt]], Table2[[#This Row],[Apt]]) -> 28 | M35: =IF(Table2[[#This Row],[Available _Nights]]=0, 0, Table2[[#This Row],[Booked_Nights]]/Table2[[#This Row],[Available _Nights]]) -> 0.78571429 | N35: =IF(Table2[[#This Row],[Booked_Nights]]=0, 0, Table2[[#This Row],[Income]]/Table2[[#This Row],[Booked_Nights]]) -> 3299.5273 | O35: =IF(L35=0,0, Table2[[#This Row],[Income]]/Table2[[#This Row],[Available _Nights]]) -> 2592.4857 | P35: =IF(Table2[[#This Row],[Income]]=0,0,Table2[[#This Row],[Total_Exp]]/Table2[[#This Row],[Income]]) -> 0.28888713
